2021-07-24 10:30:49,156 [INFO] Scheduler started
2021-07-24 10:30:50,894 [INFO] =====================BOT version: 0.0.1==============
2021-07-24 10:30:57,425 [ERROR] No error handlers are registered, logging exception.
Traceback (most recent call last):
  File "/home/lobao/.local/lib/python3.7/site-packages/telegram/ext/dispatcher.py", line 555, in process_update
    handler.handle_update(update, self, check, context)
  File "/home/lobao/.local/lib/python3.7/site-packages/telegram/ext/handler.py", line 198, in handle_update
    return self.callback(update, context)
  File "005bot.py", line 28, in start
    logMessageReceived(update,context,logger);
NameError: name 'logMessageReceived' is not defined
2021-07-24 10:31:05,447 [INFO] Received signal 2 (SIGINT), stopping...
2021-07-24 10:31:05,448 [INFO] Scheduler has been shut down
2021-07-24 10:33:14,839 [INFO] Scheduler started
2021-07-24 10:33:15,895 [INFO] =====================BOT version: 0.0.1==============
2021-07-24 10:33:42,072 [ERROR] No error handlers are registered, logging exception.
Traceback (most recent call last):
  File "/home/lobao/.local/lib/python3.7/site-packages/telegram/ext/dispatcher.py", line 555, in process_update
    handler.handle_update(update, self, check, context)
  File "/home/lobao/.local/lib/python3.7/site-packages/telegram/ext/handler.py", line 198, in handle_update
    return self.callback(update, context)
  File "005bot.py", line 28, in start
    logMessageReceived(update,context,logger);
NameError: name 'logMessageReceived' is not defined
2021-07-24 10:33:48,268 [INFO] Received signal 2 (SIGINT), stopping...
2021-07-24 10:33:48,269 [INFO] Scheduler has been shut down
2021-07-24 10:34:50,333 [INFO] Scheduler started
2021-07-24 10:34:51,542 [INFO] =====================BOT version: 0.0.1==============
2021-07-24 10:34:57,258 [INFO] RX @None(1275917999) @ PRIV: "/start"
2021-07-24 10:34:58,138 [INFO] TX @None(1275917999) @ PRIV (TXT): "It is almost done!"
2021-07-24 10:37:09,713 [ERROR] No error handlers are registered, logging exception.
Traceback (most recent call last):
  File "/home/lobao/.local/lib/python3.7/site-packages/telegram/ext/dispatcher.py", line 555, in process_update
    handler.handle_update(update, self, check, context)
  File "/home/lobao/.local/lib/python3.7/site-packages/telegram/ext/handler.py", line 198, in handle_update
    return self.callback(update, context)
  File "005bot.py", line 46, in week
    _file = fopen('data01.json');
NameError: name 'fopen' is not defined
2021-07-24 10:37:21,329 [INFO] Received signal 2 (SIGINT), stopping...
2021-07-24 10:37:21,330 [INFO] Scheduler has been shut down
2021-07-24 10:37:41,981 [INFO] Scheduler started
2021-07-24 10:37:43,269 [INFO] =====================BOT version: 0.0.1==============
2021-07-24 10:37:46,681 [ERROR] No error handlers are registered, logging exception.
Traceback (most recent call last):
  File "/home/lobao/.local/lib/python3.7/site-packages/telegram/ext/dispatcher.py", line 555, in process_update
    handler.handle_update(update, self, check, context)
  File "/home/lobao/.local/lib/python3.7/site-packages/telegram/ext/handler.py", line 198, in handle_update
    return self.callback(update, context)
  File "005bot.py", line 50, in week
    update.message.reply_text(i);
NameError: name 'i' is not defined
2021-07-24 10:37:52,198 [INFO] Received signal 2 (SIGINT), stopping...
2021-07-24 10:37:52,199 [INFO] Scheduler has been shut down
2021-07-24 10:38:06,990 [INFO] Scheduler started
2021-07-24 10:38:08,051 [INFO] =====================BOT version: 0.0.1==============
2021-07-24 10:51:09,949 [INFO] Received signal 2 (SIGINT), stopping...
2021-07-24 10:51:10,048 [INFO] Scheduler has been shut down
2021-07-24 10:51:28,361 [INFO] Scheduler started
2021-07-24 10:51:29,566 [INFO] =====================BOT version: 0.0.1==============
2021-07-24 10:52:48,707 [INFO] Received signal 2 (SIGINT), stopping...
2021-07-24 10:52:48,708 [INFO] Scheduler has been shut down
2021-07-24 10:52:59,695 [INFO] Scheduler started
2021-07-24 10:53:01,010 [INFO] =====================BOT version: 0.0.1==============
2021-07-24 10:53:06,025 [ERROR] No error handlers are registered, logging exception.
Traceback (most recent call last):
  File "/home/lobao/.local/lib/python3.7/site-packages/telegram/ext/dispatcher.py", line 555, in process_update
    handler.handle_update(update, self, check, context)
  File "/home/lobao/.local/lib/python3.7/site-packages/telegram/ext/handler.py", line 198, in handle_update
    return self.callback(update, context)
  File "005bot.py", line 47, in week
    data = json.loads(_file);
  File "/usr/lib/python3.7/json/__init__.py", line 341, in loads
    raise TypeError(f'the JSON object must be str, bytes or bytearray, '
TypeError: the JSON object must be str, bytes or bytearray, not TextIOWrapper
2021-07-24 10:53:19,213 [INFO] Received signal 2 (SIGINT), stopping...
2021-07-24 10:53:19,214 [INFO] Scheduler has been shut down
2021-07-24 10:54:34,599 [INFO] Scheduler started
2021-07-24 10:54:35,834 [INFO] =====================BOT version: 0.0.1==============
2021-07-24 10:54:53,333 [INFO] Received signal 2 (SIGINT), stopping...
2021-07-24 10:54:53,333 [INFO] Scheduler has been shut down
2021-07-24 11:01:11,145 [INFO] Scheduler started
2021-07-24 11:01:12,531 [INFO] =====================BOT version: 0.0.1==============
2021-07-24 11:01:56,611 [INFO] Received signal 2 (SIGINT), stopping...
2021-07-24 11:01:56,612 [INFO] Scheduler has been shut down
2021-07-24 11:12:23,767 [INFO] Scheduler started
2021-07-24 11:12:25,095 [INFO] =====================BOT version: 0.0.1==============
2021-07-24 11:14:53,921 [INFO] Received signal 2 (SIGINT), stopping...
2021-07-24 11:14:53,922 [INFO] Scheduler has been shut down
2021-07-24 11:15:51,024 [INFO] Scheduler started
2021-07-24 11:15:52,148 [INFO] =====================BOT version: 0.0.1==============
2021-07-24 11:17:44,928 [INFO] Received signal 2 (SIGINT), stopping...
2021-07-24 11:17:44,928 [INFO] Scheduler has been shut down
2021-07-24 11:25:16,965 [INFO] Scheduler started
2021-07-24 11:25:18,222 [INFO] =====================BOT version: 0.0.1==============
2021-07-24 11:25:22,390 [ERROR] No error handlers are registered, logging exception.
Traceback (most recent call last):
  File "/home/lobao/.local/lib/python3.7/site-packages/telegram/ext/dispatcher.py", line 555, in process_update
    handler.handle_update(update, self, check, context)
  File "/home/lobao/.local/lib/python3.7/site-packages/telegram/ext/handler.py", line 198, in handle_update
    return self.callback(update, context)
  File "005bot.py", line 47, in week
    data = json.load(_file);
  File "/usr/lib/python3.7/json/__init__.py", line 296, in load
    parse_constant=parse_constant, object_pairs_hook=object_pairs_hook, **kw)
  File "/usr/lib/python3.7/json/__init__.py", line 348, in loads
    return _default_decoder.decode(s)
  File "/usr/lib/python3.7/json/decoder.py", line 337, in decode
    obj, end = self.raw_decode(s, idx=_w(s, 0).end())
  File "/usr/lib/python3.7/json/decoder.py", line 355, in raw_decode
    raise JSONDecodeError("Expecting value", s, err.value) from None
json.decoder.JSONDecodeError: Expecting value: line 25 column 11 (char 372)
2021-07-24 11:25:34,388 [INFO] Received signal 2 (SIGINT), stopping...
2021-07-24 11:25:34,389 [INFO] Scheduler has been shut down
2021-07-24 11:28:24,490 [INFO] Scheduler started
2021-07-24 11:28:26,791 [INFO] =====================BOT version: 0.0.1==============
2021-07-24 11:30:25,065 [INFO] Received signal 2 (SIGINT), stopping...
2021-07-24 11:30:25,066 [INFO] Scheduler has been shut down
2021-07-24 11:31:11,269 [INFO] Scheduler started
2021-07-24 11:31:12,429 [INFO] =====================BOT version: 0.0.1==============
2021-07-24 11:32:18,642 [INFO] Received signal 2 (SIGINT), stopping...
2021-07-24 11:32:18,642 [INFO] Scheduler has been shut down
2021-07-24 11:32:33,356 [INFO] Scheduler started
2021-07-24 11:32:34,456 [INFO] =====================BOT version: 0.0.1==============
2021-07-24 11:32:52,775 [INFO] Received signal 2 (SIGINT), stopping...
2021-07-24 11:32:52,776 [INFO] Scheduler has been shut down
2021-07-24 11:33:53,952 [INFO] Scheduler started
2021-07-24 11:33:55,212 [INFO] =====================BOT version: 0.0.1==============
2021-07-24 11:34:55,086 [INFO] Received signal 2 (SIGINT), stopping...
2021-07-24 11:34:55,086 [INFO] Scheduler has been shut down
2021-07-24 11:35:03,436 [INFO] Scheduler started
2021-07-24 11:35:04,589 [INFO] =====================BOT version: 0.0.1==============
2021-07-24 11:35:22,658 [INFO] Received signal 2 (SIGINT), stopping...
2021-07-24 11:35:22,659 [INFO] Scheduler has been shut down
2021-07-24 11:39:04,195 [INFO] Scheduler started
2021-07-24 11:39:06,165 [INFO] =====================BOT version: 0.0.1==============
2021-07-24 11:39:21,731 [ERROR] No error handlers are registered, logging exception.
Traceback (most recent call last):
  File "/home/lobao/.local/lib/python3.7/site-packages/telegram/ext/dispatcher.py", line 555, in process_update
    handler.handle_update(update, self, check, context)
  File "/home/lobao/.local/lib/python3.7/site-packages/telegram/ext/handler.py", line 198, in handle_update
    return self.callback(update, context)
  File "005bot.py", line 73, in freeday
    update.message.reply_text(msg);
AttributeError: 'NoneType' object has no attribute 'reply_text'
2021-07-24 11:39:33,250 [INFO] Received signal 2 (SIGINT), stopping...
2021-07-24 11:39:33,251 [INFO] Scheduler has been shut down
2021-07-24 11:42:01,767 [INFO] Scheduler started
2021-07-24 11:42:03,012 [INFO] =====================BOT version: 0.0.1==============
2021-07-24 11:43:09,093 [INFO] Received signal 2 (SIGINT), stopping...
2021-07-24 11:43:09,094 [INFO] Scheduler has been shut down
2021-07-24 11:43:26,244 [INFO] Scheduler started
2021-07-24 11:43:27,434 [INFO] =====================BOT version: 0.0.1==============
2021-07-24 11:46:37,758 [INFO] Received signal 2 (SIGINT), stopping...
2021-07-24 11:46:37,759 [INFO] Scheduler has been shut down
2021-07-24 11:46:44,525 [INFO] Scheduler started
2021-07-24 11:46:45,851 [INFO] =====================BOT version: 0.0.1==============
2021-07-24 11:52:06,156 [INFO] Received signal 2 (SIGINT), stopping...
2021-07-24 11:52:06,156 [INFO] Scheduler has been shut down
2021-07-24 11:58:28,666 [INFO] Scheduler started
2021-07-24 11:58:29,871 [INFO] =====================BOT version: 0.0.1==============
2021-07-24 12:01:41,173 [INFO] RX @LuizAlves_ID(1449908736) @ PRIV: "/start"
2021-07-24 12:01:41,671 [INFO] TX @LuizAlves_ID(1449908736) @ PRIV (TXT): "It is almost done!"
2021-07-24 12:02:23,720 [INFO] Received signal 2 (SIGINT), stopping...
2021-07-24 12:02:23,721 [INFO] Scheduler has been shut down
2021-07-24 12:08:50,088 [INFO] Scheduler started
2021-07-24 12:08:51,283 [INFO] =====================BOT version: 0.0.1==============
2021-07-24 12:09:04,350 [ERROR] No error handlers are registered, logging exception.
Traceback (most recent call last):
  File "/home/lobao/.local/lib/python3.7/site-packages/telegram/ext/dispatcher.py", line 555, in process_update
    handler.handle_update(update, self, check, context)
  File "/home/lobao/.local/lib/python3.7/site-packages/telegram/ext/handler.py", line 198, in handle_update
    return self.callback(update, context)
  File "005bot.py", line 89, in plot_01
    bot.send_plot(plt);
NameError: name 'bot' is not defined
2021-07-24 12:09:13,891 [INFO] Received signal 2 (SIGINT), stopping...
2021-07-24 12:09:13,892 [INFO] Scheduler has been shut down
2021-07-24 12:11:58,360 [INFO] Scheduler started
2021-07-24 12:11:59,484 [INFO] =====================BOT version: 0.0.1==============
2021-07-24 12:12:03,640 [ERROR] No error handlers are registered, logging exception.
Traceback (most recent call last):
  File "/home/lobao/.local/lib/python3.7/site-packages/telegram/ext/dispatcher.py", line 555, in process_update
    handler.handle_update(update, self, check, context)
  File "/home/lobao/.local/lib/python3.7/site-packages/telegram/ext/handler.py", line 198, in handle_update
    return self.callback(update, context)
  File "005bot.py", line 91, in plot_01
    update.send_plot(plt);
AttributeError: 'Update' object has no attribute 'send_plot'
2021-07-24 12:12:11,348 [INFO] Received signal 2 (SIGINT), stopping...
2021-07-24 12:12:11,349 [INFO] Scheduler has been shut down
2021-07-24 15:08:50,646 [INFO] Scheduler started
2021-07-24 15:08:51,764 [INFO] =====================BOT version: 0.0.1==============
2021-07-24 15:09:17,932 [ERROR] No error handlers are registered, logging exception.
Traceback (most recent call last):
  File "/home/lobao/.local/lib/python3.7/site-packages/telegram/ext/dispatcher.py", line 555, in process_update
    handler.handle_update(update, self, check, context)
  File "/home/lobao/.local/lib/python3.7/site-packages/telegram/ext/handler.py", line 198, in handle_update
    return self.callback(update, context)
  File "005bot.py", line 90, in plot_01
    bot = TelegramBot(token)
  File "/home/lobao/.local/lib/python3.7/site-packages/bob_telegram_tools/bot.py", line 51, in __init__
    'At least one between (token, user_ids) and cred_file has to be passed.')
bob_telegram_tools.bot.InputError: At least one between (token, user_ids) and cred_file has to be passed.
2021-07-24 15:09:59,945 [INFO] Received signal 2 (SIGINT), stopping...
2021-07-24 15:09:59,946 [INFO] Scheduler has been shut down
2021-07-24 15:14:03,292 [INFO] Scheduler started
2021-07-24 15:14:04,416 [INFO] =====================BOT version: 0.0.1==============
2021-07-24 15:14:14,526 [ERROR] No error handlers are registered, logging exception.
Traceback (most recent call last):
  File "/home/lobao/.local/lib/python3.7/site-packages/telegram/ext/dispatcher.py", line 555, in process_update
    handler.handle_update(update, self, check, context)
  File "/home/lobao/.local/lib/python3.7/site-packages/telegram/ext/handler.py", line 198, in handle_update
    return self.callback(update, context)
  File "005bot.py", line 95, in plot_01
    update.send_plot(plt);
AttributeError: 'Update' object has no attribute 'send_plot'
2021-07-24 15:14:22,667 [INFO] Received signal 2 (SIGINT), stopping...
2021-07-24 15:14:22,667 [INFO] Scheduler has been shut down
2021-07-24 15:15:26,915 [INFO] Scheduler started
2021-07-24 15:15:28,058 [INFO] =====================BOT version: 0.0.1==============
2021-07-24 15:15:38,503 [ERROR] No error handlers are registered, logging exception.
Traceback (most recent call last):
  File "/home/lobao/.local/lib/python3.7/site-packages/telegram/ext/dispatcher.py", line 555, in process_update
    handler.handle_update(update, self, check, context)
  File "/home/lobao/.local/lib/python3.7/site-packages/telegram/ext/handler.py", line 198, in handle_update
    return self.callback(update, context)
  File "005bot.py", line 95, in plot_01
    bot.send_plot(plt);
  File "/home/lobao/.local/lib/python3.7/site-packages/bob_telegram_tools/bot.py", line 132, in send_plot
    return self.bot.send_photo(self.user_ids, open(img_path, 'rb'))
  File "/home/lobao/.local/lib/python3.7/site-packages/telegram/bot.py", line 130, in decorator
    result = func(*args, **kwargs)
  File "/home/lobao/.local/lib/python3.7/site-packages/telegram/bot.py", line 707, in send_photo
    api_kwargs=api_kwargs,
  File "/home/lobao/.local/lib/python3.7/site-packages/telegram/bot.py", line 332, in _message
    result = self._post(endpoint, data, timeout=timeout, api_kwargs=api_kwargs)
  File "/home/lobao/.local/lib/python3.7/site-packages/telegram/bot.py", line 296, in _post
    f'{self.base_url}/{endpoint}', data=data, timeout=effective_timeout
  File "/home/lobao/.local/lib/python3.7/site-packages/telegram/utils/request.py", line 354, in post
    result = self._request_wrapper('POST', url, fields=data, **urlopen_kwargs)
  File "/home/lobao/.local/lib/python3.7/site-packages/telegram/utils/request.py", line 277, in _request_wrapper
    raise Unauthorized(message)
telegram.error.Unauthorized: Forbidden: bot can't send messages to bots
2021-07-24 15:17:34,175 [INFO] Received signal 2 (SIGINT), stopping...
2021-07-24 15:17:34,176 [INFO] Scheduler has been shut down
2021-07-24 15:24:32,556 [INFO] Scheduler started
2021-07-24 15:24:33,964 [INFO] =====================BOT version: 0.0.1==============
2021-07-24 15:24:43,486 [ERROR] No error handlers are registered, logging exception.
Traceback (most recent call last):
  File "/home/lobao/.local/lib/python3.7/site-packages/telegram/ext/dispatcher.py", line 555, in process_update
    handler.handle_update(update, self, check, context)
  File "/home/lobao/.local/lib/python3.7/site-packages/telegram/ext/handler.py", line 198, in handle_update
    return self.callback(update, context)
  File "005bot.py", line 97, in plot_01
    update.message.reply_photo('mgraph.png');
  File "/home/lobao/.local/lib/python3.7/site-packages/telegram/message.py", line 1017, in reply_photo
    filename=filename,
  File "/home/lobao/.local/lib/python3.7/site-packages/telegram/bot.py", line 130, in decorator
    result = func(*args, **kwargs)
  File "/home/lobao/.local/lib/python3.7/site-packages/telegram/bot.py", line 707, in send_photo
    api_kwargs=api_kwargs,
  File "/home/lobao/.local/lib/python3.7/site-packages/telegram/ext/extbot.py", line 207, in _message
    api_kwargs=api_kwargs,
  File "/home/lobao/.local/lib/python3.7/site-packages/telegram/bot.py", line 332, in _message
    result = self._post(endpoint, data, timeout=timeout, api_kwargs=api_kwargs)
  File "/home/lobao/.local/lib/python3.7/site-packages/telegram/bot.py", line 296, in _post
    f'{self.base_url}/{endpoint}', data=data, timeout=effective_timeout
  File "/home/lobao/.local/lib/python3.7/site-packages/telegram/utils/request.py", line 361, in post
    **urlopen_kwargs,
  File "/home/lobao/.local/lib/python3.7/site-packages/telegram/utils/request.py", line 279, in _request_wrapper
    raise BadRequest(message)
telegram.error.BadRequest: Unsupported url protocol
2021-07-24 15:24:51,992 [INFO] Received signal 2 (SIGINT), stopping...
2021-07-24 15:24:51,993 [INFO] Scheduler has been shut down
2021-07-24 15:26:05,935 [INFO] Scheduler started
2021-07-24 15:26:07,255 [INFO] =====================BOT version: 0.0.1==============
2021-07-24 15:26:12,285 [ERROR] No error handlers are registered, logging exception.
Traceback (most recent call last):
  File "/home/lobao/.local/lib/python3.7/site-packages/telegram/ext/dispatcher.py", line 555, in process_update
    handler.handle_update(update, self, check, context)
  File "/home/lobao/.local/lib/python3.7/site-packages/telegram/ext/handler.py", line 198, in handle_update
    return self.callback(update, context)
  File "005bot.py", line 96, in plot_01
    update.message.reply_photo('mgraph.png');
  File "/home/lobao/.local/lib/python3.7/site-packages/telegram/message.py", line 1017, in reply_photo
    filename=filename,
  File "/home/lobao/.local/lib/python3.7/site-packages/telegram/bot.py", line 130, in decorator
    result = func(*args, **kwargs)
  File "/home/lobao/.local/lib/python3.7/site-packages/telegram/bot.py", line 707, in send_photo
    api_kwargs=api_kwargs,
  File "/home/lobao/.local/lib/python3.7/site-packages/telegram/ext/extbot.py", line 207, in _message
    api_kwargs=api_kwargs,
  File "/home/lobao/.local/lib/python3.7/site-packages/telegram/bot.py", line 332, in _message
    result = self._post(endpoint, data, timeout=timeout, api_kwargs=api_kwargs)
  File "/home/lobao/.local/lib/python3.7/site-packages/telegram/bot.py", line 296, in _post
    f'{self.base_url}/{endpoint}', data=data, timeout=effective_timeout
  File "/home/lobao/.local/lib/python3.7/site-packages/telegram/utils/request.py", line 361, in post
    **urlopen_kwargs,
  File "/home/lobao/.local/lib/python3.7/site-packages/telegram/utils/request.py", line 279, in _request_wrapper
    raise BadRequest(message)
telegram.error.BadRequest: Unsupported url protocol
2021-07-24 15:26:44,194 [INFO] Received signal 2 (SIGINT), stopping...
2021-07-24 15:26:44,195 [INFO] Scheduler has been shut down
2021-07-24 15:27:01,898 [INFO] Scheduler started
2021-07-24 15:27:03,061 [INFO] =====================BOT version: 0.0.1==============
2021-07-24 15:27:08,383 [ERROR] No error handlers are registered, logging exception.
Traceback (most recent call last):
  File "/home/lobao/.local/lib/python3.7/site-packages/telegram/ext/dispatcher.py", line 555, in process_update
    handler.handle_update(update, self, check, context)
  File "/home/lobao/.local/lib/python3.7/site-packages/telegram/ext/handler.py", line 198, in handle_update
    return self.callback(update, context)
  File "005bot.py", line 95, in plot_01
    update.message.reply_photo('mgraph.png');
  File "/home/lobao/.local/lib/python3.7/site-packages/telegram/message.py", line 1017, in reply_photo
    filename=filename,
  File "/home/lobao/.local/lib/python3.7/site-packages/telegram/bot.py", line 130, in decorator
    result = func(*args, **kwargs)
  File "/home/lobao/.local/lib/python3.7/site-packages/telegram/bot.py", line 707, in send_photo
    api_kwargs=api_kwargs,
  File "/home/lobao/.local/lib/python3.7/site-packages/telegram/ext/extbot.py", line 207, in _message
    api_kwargs=api_kwargs,
  File "/home/lobao/.local/lib/python3.7/site-packages/telegram/bot.py", line 332, in _message
    result = self._post(endpoint, data, timeout=timeout, api_kwargs=api_kwargs)
  File "/home/lobao/.local/lib/python3.7/site-packages/telegram/bot.py", line 296, in _post
    f'{self.base_url}/{endpoint}', data=data, timeout=effective_timeout
  File "/home/lobao/.local/lib/python3.7/site-packages/telegram/utils/request.py", line 361, in post
    **urlopen_kwargs,
  File "/home/lobao/.local/lib/python3.7/site-packages/telegram/utils/request.py", line 279, in _request_wrapper
    raise BadRequest(message)
telegram.error.BadRequest: Unsupported url protocol
2021-07-24 15:27:13,364 [INFO] Received signal 2 (SIGINT), stopping...
2021-07-24 15:27:13,365 [INFO] Scheduler has been shut down
2021-07-24 15:32:11,756 [INFO] Scheduler started
2021-07-24 15:32:12,826 [INFO] =====================BOT version: 0.0.1==============
2021-07-24 15:32:16,524 [ERROR] No error handlers are registered, logging exception.
Traceback (most recent call last):
  File "/home/lobao/.local/lib/python3.7/site-packages/telegram/ext/dispatcher.py", line 555, in process_update
    handler.handle_update(update, self, check, context)
  File "/home/lobao/.local/lib/python3.7/site-packages/telegram/ext/handler.py", line 198, in handle_update
    return self.callback(update, context)
  File "005bot.py", line 95, in plot_01
    update.message.reply_photo(open('mgraph.png','r'));
  File "/home/lobao/.local/lib/python3.7/site-packages/telegram/message.py", line 1017, in reply_photo
    filename=filename,
  File "/home/lobao/.local/lib/python3.7/site-packages/telegram/bot.py", line 130, in decorator
    result = func(*args, **kwargs)
  File "/home/lobao/.local/lib/python3.7/site-packages/telegram/bot.py", line 689, in send_photo
    'photo': parse_file_input(photo, PhotoSize, filename=filename),
  File "/home/lobao/.local/lib/python3.7/site-packages/telegram/utils/helpers.py", line 143, in parse_file_input
    return InputFile(file_input, attach=attach, filename=filename)
  File "/home/lobao/.local/lib/python3.7/site-packages/telegram/files/inputfile.py", line 62, in __init__
    self.input_file_content = obj.read()
  File "/usr/lib/python3.7/codecs.py", line 322, in decode
    (result, consumed) = self._buffer_decode(data, self.errors, final)
UnicodeDecodeError: 'utf-8' codec can't decode byte 0x89 in position 0: invalid start byte
2021-07-24 15:32:27,120 [INFO] Received signal 2 (SIGINT), stopping...
2021-07-24 15:32:27,121 [INFO] Scheduler has been shut down
2021-07-24 15:48:07,421 [INFO] Scheduler started
2021-07-24 15:48:08,683 [INFO] =====================BOT version: 0.0.1==============
2021-07-24 15:48:31,035 [INFO] Received signal 2 (SIGINT), stopping...
2021-07-24 15:48:31,036 [INFO] Scheduler has been shut down
2021-07-24 15:50:06,359 [INFO] Scheduler started
2021-07-24 15:50:07,568 [INFO] =====================BOT version: 0.0.1==============
2021-07-24 15:51:13,814 [INFO] Received signal 2 (SIGINT), stopping...
2021-07-24 15:51:13,814 [INFO] Scheduler has been shut down
2021-07-24 16:15:12,216 [INFO] Scheduler started
2021-07-24 16:15:13,426 [INFO] =====================BOT version: 0.0.1==============
2021-07-24 16:16:03,660 [INFO] Received signal 2 (SIGINT), stopping...
2021-07-24 16:16:03,661 [INFO] Scheduler has been shut down
2021-07-24 16:27:20,896 [INFO] Scheduler started
2021-07-24 16:27:22,132 [INFO] =====================BOT version: 0.0.1==============
2021-07-24 16:27:52,632 [INFO] Received signal 2 (SIGINT), stopping...
2021-07-24 16:27:52,633 [INFO] Scheduler has been shut down
2021-07-24 16:28:01,207 [INFO] Scheduler started
2021-07-24 16:28:02,492 [INFO] =====================BOT version: 0.0.1==============
2021-07-24 16:28:13,411 [ERROR] No error handlers are registered, logging exception.
Traceback (most recent call last):
  File "/home/lobao/.local/lib/python3.7/site-packages/telegram/ext/dispatcher.py", line 555, in process_update
    handler.handle_update(update, self, check, context)
  File "/home/lobao/.local/lib/python3.7/site-packages/telegram/ext/handler.py", line 198, in handle_update
    return self.callback(update, context)
  File "005bot.py", line 104, in plot_01
    print(len(x['hora']));
TypeError: object of type 'NoneType' has no len()
2021-07-24 16:28:20,659 [INFO] Received signal 2 (SIGINT), stopping...
2021-07-24 16:28:20,660 [INFO] Scheduler has been shut down
2021-07-24 16:32:17,691 [INFO] Scheduler started
2021-07-24 16:32:18,794 [INFO] =====================BOT version: 0.0.1==============
2021-07-24 16:33:00,403 [INFO] Received signal 2 (SIGINT), stopping...
2021-07-24 16:33:00,404 [INFO] Scheduler has been shut down
2021-07-24 16:33:09,044 [INFO] Scheduler started
2021-07-24 16:33:10,200 [INFO] =====================BOT version: 0.0.1==============
2021-07-24 16:33:26,256 [INFO] Received signal 2 (SIGINT), stopping...
2021-07-24 16:33:26,256 [INFO] Scheduler has been shut down
2021-07-24 16:42:12,670 [INFO] Scheduler started
2021-07-24 16:42:13,834 [INFO] =====================BOT version: 0.0.1==============
2021-07-24 16:42:57,587 [INFO] Received signal 2 (SIGINT), stopping...
2021-07-24 16:42:57,587 [INFO] Scheduler has been shut down
2021-07-24 16:43:51,286 [INFO] Scheduler started
2021-07-24 16:43:52,436 [INFO] =====================BOT version: 0.0.1==============
2021-07-24 16:46:25,370 [INFO] Received signal 2 (SIGINT), stopping...
2021-07-24 16:46:25,464 [INFO] Scheduler has been shut down
2021-07-24 16:47:10,897 [INFO] Scheduler started
2021-07-24 16:47:11,917 [INFO] =====================BOT version: 0.0.1==============
2021-07-24 16:50:51,034 [INFO] Received signal 2 (SIGINT), stopping...
2021-07-24 16:50:51,035 [INFO] Scheduler has been shut down
2021-07-24 16:51:24,968 [INFO] Scheduler started
2021-07-24 16:51:26,263 [INFO] =====================BOT version: 0.0.1==============
2021-07-24 16:51:50,405 [INFO] Received signal 2 (SIGINT), stopping...
2021-07-24 16:51:50,406 [INFO] Scheduler has been shut down
2021-07-24 16:52:40,341 [INFO] Scheduler started
2021-07-24 16:52:41,733 [INFO] =====================BOT version: 0.0.1==============
2021-07-24 16:53:07,953 [INFO] Received signal 2 (SIGINT), stopping...
2021-07-24 16:53:07,954 [INFO] Scheduler has been shut down
2021-07-24 16:56:27,657 [INFO] Scheduler started
2021-07-24 16:56:29,057 [INFO] =====================BOT version: 0.0.1==============
2021-07-24 16:56:42,643 [INFO] RX @None(1275917999) @ PRIV: "/start"
2021-07-24 16:56:43,559 [INFO] TX @None(1275917999) @ PRIV (TXT): "It is almost done!"
2021-07-24 16:58:04,690 [INFO] Received signal 2 (SIGINT), stopping...
2021-07-24 16:58:04,691 [INFO] Scheduler has been shut down
2021-07-24 17:10:59,428 [INFO] Scheduler started
2021-07-24 17:11:00,461 [INFO] =====================BOT version: 0.0.1==============
2021-07-24 17:12:02,106 [ERROR] No error handlers are registered, logging exception.
Traceback (most recent call last):
  File "/home/lobao/.local/lib/python3.7/site-packages/telegram/ext/dispatcher.py", line 555, in process_update
    handler.handle_update(update, self, check, context)
  File "/home/lobao/.local/lib/python3.7/site-packages/telegram/ext/handler.py", line 198, in handle_update
    return self.callback(update, context)
  File "005bot.py", line 82, in freeday
    update.message.reply_text(msg);
AttributeError: 'NoneType' object has no attribute 'reply_text'
2021-07-24 17:12:24,253 [INFO] Received signal 2 (SIGINT), stopping...
2021-07-24 17:12:24,253 [INFO] Scheduler has been shut down
2021-07-24 17:13:30,820 [INFO] Scheduler started
2021-07-24 17:13:32,002 [INFO] =====================BOT version: 0.0.1==============
2021-07-24 17:14:18,040 [INFO] Received signal 2 (SIGINT), stopping...
2021-07-24 17:14:18,138 [INFO] Scheduler has been shut down
2021-07-24 17:20:37,975 [INFO] Scheduler started
2021-07-24 17:20:39,455 [INFO] =====================BOT version: 0.0.1==============
2021-07-24 17:20:47,251 [INFO] RX @None(1275917999) @ PRIV: "/start"
2021-07-24 17:20:48,168 [INFO] TX @None(1275917999) @ PRIV (TXT): "Bem Vindo ao Agend\n\n\nPara Criar um evento, digite /create <empresa> <horario> <dia_da_semana>\n\nDigite /help, para mais ajuda!"
2021-07-24 17:21:34,076 [INFO] Received signal 2 (SIGINT), stopping...
2021-07-24 17:21:34,167 [INFO] Scheduler has been shut down
2021-07-24 17:22:00,412 [INFO] Scheduler started
2021-07-24 17:22:01,686 [INFO] =====================BOT version: 0.0.1==============
2021-07-24 17:22:07,822 [INFO] RX @None(1275917999) @ PRIV: "/start"
2021-07-24 17:22:08,649 [INFO] TX @None(1275917999) @ PRIV (TXT): "Bem Vindo ao Agend\n\n\nPara Criar um evento,digite:\n/create <empresa> <horario> <dia_da_semana>\n\nDigite /help, para mais ajuda!"
2021-07-24 17:25:23,129 [INFO] Received signal 2 (SIGINT), stopping...
2021-07-24 17:25:23,225 [INFO] Scheduler has been shut down
